File: EGR101/ExData3.csv
Stress and strain data from a mechanical pull test*
*
Strain (uin/in)*Stress (MPa)
0.3*16.98786574
0.6*32.70884646
0.9*6.481164947
1.2*-0.466849063
1.5*29.6881538
1.8*9.987566243
2.1*10.54412497
2.4*1.08114358
2.7*0.53524819
3*7.821123704
3.3*-0.726469465
3.6*-2.431833891
3.9*14.1857541
4.2*27.10227322
4.5*10.43498024
4.8*23.43167651
5.1*26.77700939
5.4*-4.6631021
5.7*24.25470989
6*32.69306787
6.3*21.94545456
6.6*1.920720066
6.9*20.96374713
7.2*33.51098842
7.5*14.13667983
7.8*27.28433707
8.1*42.80770774
8.4*16.43298009
8.7*17.30663419
9*18.20170405
9.3*16.43531454
9.6*22.89611536
9.9*-0.309588893
10.2*16.79946212
10.5*8.968477322
10.8*23.02875948
11.1*10.46254386
11.4*15.92086716
11.7*6.746856302
12*25.15017288
12.3*33.78536564
12.6*16.38741732
12.9*-21.78420377
13.2*7.800030541
13.5*18.22219264
13.8*25.50765232
14.1*33.72132985
14.4*18.9959832
14.7*15.5316318
15*4.887381063
15.3*-1.925414262
15.6*12.61600781
15.9*-0.272624227
16.2*20.71195318
16.5*11.44035034
16.8*21.76929505
17.1*28.22568181
17.4*38.60286588
17.7*21.78307739
18*19.71416402
18.3*22.28181391
18.6*20.01670653
18.9*-5.464195146
19.2*33.88982058
19.5*-14.85906753
19.8*0.027094392
20.1*17.18037614
20.4*18.43844919
20.7*30.22293774
21*2.638222718
21.3*17.24675331
21.6*14.12894527
21.9*17.09685813
22.2*38.12899644
22.5*17.68828857
22.8*19.69936361
23.1*17.44939565
23.4*23.99083283
23.7*19.59315649
24*31.44990234
24.3*27.88515132
24.6*7.896673213
24.9*11.0792843
25.2*3.67070904
25.5*21.83120703
25.8*22.31646039
26.1*9.093387881
26.4*28.94380341
26.7*23.87699615
27*3.66999515
27.3*31.94289718
27.6*34.04537929
27.9*26.30844673
28.2*0.797387207
28.5*31.37507488
28.8*16.04132693
29.1*12.24184795
29.4*5.486509019
29.7*21.9055516
30*18.89765739
30.3*20.20131437
30.6*3.173586818
30.9*21.69255211
31.2*29.18268352
31.5*20.96499652
31.8*27.43340734
32.1*-1.265298546
32.4*20.56311743
32.7*18.17050449
33*5.718630472
33.3*15.10792867
33.6*3.676972209
33.9*31.74827444
34.2*10.92803287
34.5*16.9738402
34.8*13.88542867
35.1*14.98950562
35.4*19.27447278
35.7*15.12384407
36*5.913481077
36.3*13.88265204
36.6*5.31553426
36.9*27.03348239
37.2*53.67083657
37.5*26.37979952
37.8*13.38791538
38.1*19.78146969
38.4*38.77401742
38.7*20.54771834
39*25.63513185
39.3*20.79634648
39.6*32.25661348
39.9*29.28094829
40.2*44.89087694
40.5*11.05106987
40.8*16.94850686
41.1*14.44111729
41.4*32.51897849
41.7*10.62571777
42*10.14497921
42.3*23.31748081
42.6*21.57912844
42.9*4.841697767
43.2*6.802566154
43.5*6.427189195
43.8*41.3351546
44.1*40.83262197
44.4*34.86268851
44.7*38.40547253
45*17.41416195
45.3*18.00239524
45.6*35.56680627
45.9*15.98811761
46.2*11.41196704
46.5*23.42985306
46.8*20.58807942
47.1*23.28514099
47.4*21.46831356
47.7*18.07038982
48*16.67643923
48.3*19.53204394
48.6*24.09510658
48.9*34.43579811
49.2*41.98696512
49.5*6.38157281
49.8*29.7608275
50.1*38.18009046
50.4*32.47350861
50.7*21.2381585
51*14.22986422
51.3*18.7722171
51.6*19.23359201
51.9*-0.323200353
52.2*16.04796967
52.5*24.31127638
52.8*14.87156251
53.1*30.72098975
53.4*23.5978869
53.7*14.36459213
54*25.09317627
54.3*23.6212604
54.6*11.81053198
54.9*23.77402881
55.2*20.32252253
55.5*13.4142389
55.8*1.001938785
56.1*38.84791373
56.4*42.8019474
56.7*-3.359756067
57*13.87541218
57.3*18.68208972
57.6*29.83982892
57.9*36.64055262
58.2*19.53949689
58.5*22.18041986
58.8*22.76003348
59.1*29.1232809
59.4*37.67605638
59.7*36.21270749
60*27.32697583
60.3*31.68861391
60.6*35.31623883
60.9*28.02551013
61.2*39.31901436
61.5*27.03187718
61.8*34.7275174
62.1*12.6651705
62.4*15.77021019
62.7*55.50465426
63*17.46624227
63.3*30.98164741
63.6*15.07902107
63.9*10.10957698
64.2*6.880907709
64.5*12.26700224
64.8*37.58573239
65.1*32.65903924
65.4*20.00231577
65.7*33.51302896
66*31.00150889
66.3*9.209223555
66.6*30.93201165
66.9*37.45489603
67.2*36.49288806
67.5*16.14102364
67.8*24.84449363
68.1*28.96153576
68.4*23.31651753
68.7*18.87872944
69*28.56316136
69.3*28.00341414
69.6*40.82937585
69.9*29.95014632
70.2*34.53544299
70.5*34.25809699
70.8*-0.811643699
71.1*32.25547362
71.4*29.91100597
71.7*25.7742546
72*23.03532162
72.3*37.98551387
72.6*58.34483956
72.9*40.29058926
73.2*22.13571882
73.5*30.35679926
73.8*52.01052651
74.1*24.06954727
74.4*31.94131384
74.7*46.94001034
75*41.26263085
75.3*28.10724548
75.6*21.76480714
75.9*45.50657644
76.2*30.76326572
76.5*45.42966288
76.8*28.62100931
77.1*58.17180544
77.4*35.89913082
77.7*34.52594268
78*34.15799935
78.3*32.74413059
78.6*16.8340637
78.9*35.93723842
79.2*11.4386864
79.5*11.41967707
79.8*31.15560631
80.1*19.34874806
80.4*30.02606437
80.7*53.2746421
81*27.82507942
81.3*39.74388219
81.6*18.68896615
81.9*35.90587177
82.2*16.14657783
82.5*44.31366807
82.8*21.00327742
83.1*25.993286
83.4*29.20385508
83.7*38.5930012
84*21.28599225
84.3*33.91758668
84.6*17.92279218
84.9*32.92480997
85.2*19.37559507
85.5*28.81555453
85.8*38.86283646
86.1*28.30993009
86.4*27.07124767
86.7*24.78374462
87*28.66134319
87.3*11.85190371
87.6*28.27423926
87.9*15.82088308
88.2*42.18741423
88.5*42.90024309
88.8*38.99002669
89.1*30.66771517
89.4*58.73184232
89.7*40.5108777
90*39.18840348
90.3*13.64422524
90.6*39.46875509
90.9*49.24638719
91.2*42.69861308
91.5*11.21751426
91.8*37.9212923
92.1*36.55882226
92.4*49.74862541
92.7*44.81554514
93*33.04452148
93.3*16.73221776
93.6*39.21748065
93.9*35.69242802
94.2*43.47795823
94.5*27.95617203
94.8*42.37678103
95.1*27.2840647
95.4*17.59970509
95.7*56.23780929
96*27.98777904
96.3*27.79418729
96.6*40.07815126
96.9*25.99378125
97.2*40.19677359
97.5*27.24891088
97.8*39.29291859
98.1*36.86145347
98.4*36.69612265
98.7*39.19844858
99*41.80400149
99.3*36.25908691
99.6*19.39765594
99.9*41.62400501
100.2*8.570472195
100.5*47.7231812
100.8*56.78746999
101.1*30.67307028
101.4*55.18218932
101.7*54.99922813
102*28.87641641
102.3*31.44354469
102.6*29.76398192
102.9*49.41064793
103.2*33.91261981
103.5*29.74062158
103.8*39.32090194
104.1*31.92308796
104.4*19.66151041
104.7*49.00841345
105*51.03790315
105.3*25.35847591
105.6*31.59639405
105.9*30.49870786
106.2*33.58413138
106.5*30.55522897
106.8*18.51610476
107.1*48.96069908
107.4*30.83664871
107.7*21.16410642
108*46.58060667
108.3*37.89739105
108.6*24.95923016
108.9*44.05981876
109.2*39.90231719
109.5*69.47090601
109.8*30.37810093
110.1*22.09514371
110.4*58.25971782
110.7*30.88979985
111*34.78234084
111.3*52.16845037
111.6*15.16230736
111.9*39.05772211
112.2*43.62831874
112.5*67.82697094
112.8*28.27086349
113.1*43.10414443
113.4*48.56677899
113.7*23.21660167
114*45.27460335
114.3*47.6810251
114.6*46.56763951
114.9*42.43801262
115.2*15.09222159
115.5*34.64523266
115.8*40.46731675
116.1*51.51757829
116.4*24.55404704
116.7*71.06237459
117*43.90047776
117.3*38.82265685
117.6*39.57945885
117.9*42.93842561
118.2*24.14802317
118.5*23.84486956
118.8*50.34236006
119.1*59.2468302
119.4*42.54041161
119.7*37.15733064
120*29.58524331
120.3*47.29406998
120.6*36.45167693
120.9*45.80161976
121.2*49.2480888
121.5*35.38380115
121.8*36.42500565
122.1*35.93050632
122.4*58.49466271
122.7*44.29515712
123*33.65798782
123.3*61.06837733
123.6*43.60372001
123.9*54.60874928
124.2*32.24382126
124.5*19.02215783
124.8*52.53403997
125.1*40.89053196
125.4*54.18243254
125.7*42.57836306
126*48.89296938
126.3*31.47156236
126.6*41.87339313
126.9*36.87360568
127.2*30.37648026
127.5*46.64813238
127.8*11.77363744
128.1*36.01319337
128.4*50.62550125
128.7*66.70336248
129*56.50975484
129.3*56.88565483
129.6*37.41171385
129.9*29.77354403
130.2*58.61310416
130.5*21.71079229
130.8*51.20300513
131.1*33.51870775
131.4*77.02004026
131.7*39.99750804
132*36.23906073
132.3*50.25920359
132.6*24.21707298
132.9*41.87916449
133.2*59.38809168
133.5*34.66119836
133.8*43.69496302
134.1*39.64918906
134.4*24.37874335
134.7*60.15698998
135*57.57290664
135.3*47.27839423
135.6*61.81501515
135.9*54.27075276
136.2*60.24145198
136.5*30.23286557
136.8*41.21759429
137.1*50.50068714
137.4*48.30056692
137.7*45.0464972
138*48.18366386
138.3*36.56224169
138.6*73.39670104
138.9*28.23534001
139.2*45.23414625
139.5*47.24046018
139.8*66.85034841
140.1*35.08411507
140.4*50.82916033
140.7*63.90350619
141*65.11068412
141.3*67.60465863
141.6*48.69112913
141.9*52.88078088
142.2*48.33155512
142.5*43.18061485
142.8*30.83123314
143.1*35.25874173
143.4*60.44974274
143.7*53.07620401
144*36.06284834
144.3*56.8437743
144.6*47.94036293
144.9*37.40222666
145.2*38.10542324
145.5*24.8551527
145.8*67.51784045
146.1*36.13267169
146.4*37.56906278
146.7*40.37158237
147*16.81860428
147.3*45.3055347
147.6*59.18342074
147.9*46.56017029
148.2*58.73201183
148.5*48.14564683
148.8*52.74244985
149.1*47.99435436
149.4*27.20830131
149.7*58.05476017
150*74.60726092
150.3*41.09603808
150.6*40.17555815
150.9*49.34184221
151.2*35.63924427
151.5*30.34380851
151.8*58.28143686
152.1*47.08674921
152.4*57.40622297
152.7*44.55362035
153*41.93408758
153.3*28.1469352
153.6*37.40762043
153.9*45.40921046
154.2*34.53865571
154.5*63.22878939
154.8*69.3161304
155.1*37.73684546
155.4*47.76351833
155.7*33.47023708
156*29.04561057
156.3*42.81464222
156.6*47.14079468
156.9*42.90199443
157.2*51.84756254
157.5*46.91399288
157.8*58.60279602
158.1*61.00357874
158.4*58.54373648
158.7*34.05277934
159*46.10758411
159.3*66.22982275
159.6*26.41111373
159.9*54.53269676
160.2*61.79373444
160.5*50.29600391
160.8*24.49539265
161.1*67.91244535
161.4*52.14757723
161.7*48.74594253
162*61.55400421
162.3*38.49814859
162.6*46.70287951
162.9*60.37874854
163.2*50.58596215
163.5*49.21552041
163.8*60.37702387
164.1*63.73024518
164.4*57.64174868
164.7*52.75310759
165*55.27746593
165.3*57.45039581
165.6*47.11453038
165.9*47.04351984
166.2*79.03721354
166.5*54.69643154
166.8*35.33789649
167.1*50.55814297
167.4*60.68840602
167.7*44.00072014
168*56.48273191
168.3*29.95231565
168.6*71.38046366
168.9*47.75350386
169.2*56.33455831
169.5*46.64445615
169.8*52.49712819
170.1*64.56974366
170.4*33.33667041
170.7*41.91576866
171*63.72082791
171.3*58.06268009
171.6*34.46887418
171.9*51.29055346
172.2*68.0155205
172.5*43.86006842
172.8*34.02618872
173.1*60.89445344
173.4*71.23803295
173.7*52.77634648
174*38.75793054
174.3*69.03387397
174.6*33.26144282
174.9*44.85194579
175.2*45.97821553
175.5*69.0227114
175.8*54.48484839
176.1*36.2563263
176.4*68.33584002
176.7*43.96961039
177*61.85672613
177.3*36.72046127
177.6*41.31014105
177.9*52.45955639
178.2*42.2349753
178.5*57.21684393
178.8*57.3840846
179.1*71.34835275
179.4*47.94218113
179.7*49.02252583
180*62.37729571
180.3*57.01778266
180.6*55.71601123
180.9*86.02217613
181.2*34.82915467
181.5*49.83846042
181.8*56.28896426
182.1*53.54629345
182.4*49.82097744
182.7*44.99042196
183*29.62518303
183.3*38.93938258
183.6*57.84033724
183.9*58.32169462
184.2*49.98057262
184.5*67.01176131
184.8*27.15798834
185.1*56.81356286
185.4*49.24473886
185.7*51.91446801
186*44.47766078
186.3*80.90488238
186.6*72.82060856
186.9*57.60540769
187.2*51.57659598
187.5*60.27183145
187.8*54.63212904
188.1*74.58049416
188.4*47.60958913
188.7*62.33989248
189*64.65579834
189.3*48.47879407
189.6*39.83364211
189.9*61.47598723
190.2*53.96185681
190.5*57.11729584
190.8*86.83077666
191.1*63.50906044
191.4*65.0989649
191.7*51.45790121
192*35.66971306
192.3*54.43150788
192.6*64.37594808
192.9*53.2764213
193.2*60.10100381
193.5*55.23238967
193.8*48.40691616
194.1*60.56442629
194.4*59.60528023
194.7*68.98423319
195*64.92697941
195.3*70.74733428
195.6*49.540531
195.9*69.24355876
196.2*52.66497091
196.5*61.59821752
196.8*40.99265624
197.1*56.16809134
197.4*72.94886666
197.7*51.36459282
198*64.27025152
198.3*78.31141062
198.6*51.41929097
198.9*59.92272717
199.2*56.32615129
199.5*79.48551691
199.8*55.10298015
200.1*69.26080787
200.4*36.44845275
200.7*30.55288724
201*71.37183906
201.3*73.53937755
201.6*64.80953428
201.9*43.61239231
202.2*55.38578549
202.5*42.92710214
202.8*53.23741979
203.1*71.24160437
203.4*69.21891051
203.7*57.47159242
204*54.82719422
204.3*47.03819685
204.6*64.32303994
204.9*53.29020488
205.2*56.45044235
205.5*75.95120587
205.8*49.1737243
206.1*61.99842813
206.4*78.86152052
206.7*70.1574331
207*61.91170753
207.3*62.52726862
207.6*71.80503499
207.9*60.4014329
208.2*98.91763494
208.5*70.08299345
208.8*52.35300781
209.1*61.84668203
209.4*57.99965793
209.7*84.01907928
210*85.57279861
210.3*54.72439374
210.6*82.35786683
210.9*60.67626459
211.2*68.33928061
211.5*44.5410129
211.8*59.80640256
212.1*59.96246502
212.4*46.42674535
212.7*55.45231829
213*62.09593354
213.3*42.20634217
213.6*52.1570681
213.9*62.98041998
214.2*75.47980072
214.5*51.11764408
214.8*63.83964799
215.1*60.01267952
215.4*43.69369744
215.7*21.21993081
216*60.46982358
216.3*64.01805314
216.6*64.6465403
216.9*46.04747296
217.2*57.94985623
217.5*65.58562072
217.8*35.91168306
218.1*86.10146223
218.4*32.84801326
218.7*58.57399561
219*62.81073776
219.3*66.04582336
219.6*49.94156994
219.9*37.00695141
220.2*54.89707265
220.5*69.44615943
220.8*40.37201904
221.1*51.01591329
221.4*79.33235859
221.7*80.7305531
222*101.6531723
222.3*70.11575069
222.6*70.491732
222.9*75.11455328
223.2*66.08714059
223.5*62.97931849
223.8*74.34051353
224.1*47.21507978
224.4*74.15499483
224.7*44.11297935
225*75.9333349
225.3*65.47336587
225.6*70.25721879
225.9*87.17298552
226.2*53.47184308
226.5*71.34934799
226.8*59.84552706
227.1*56.1470428
227.4*43.10996324
227.7*56.00665765
228*62.09864012
228.3*49.9504278
228.6*57.56295717
228.9*66.2844512
229.2*76.61868345
229.5*62.68609379
229.8*74.52750329
230.1*76.09208263
230.4*63.89333752
230.7*83.11528576
231*65.52360411
231.3*64.75020905
231.6*70.71601527
231.9*64.1630191
232.2*56.8698498
232.5*47.38699627
232.8*63.26909025
233.1*69.20191827
233.4*73.96528643
233.7*78.75017433
234*44.70806615
234.3*56.76735954
234.6*45.05351662
234.9*44.47489739
235.2*89.53263938
235.5*62.28427551
235.8*69.52509817
236.1*71.42007985
236.4*75.87255371
236.7*76.89332592
237*76.6295094
237.3*76.07340947
237.6*61.07175557
237.9*62.63853115
238.2*57.17859587
238.5*68.67851152
238.8*58.06965878
239.1*72.03549523
239.4*65.82413823
239.7*59.08145719
240*75.82137659
240.3*76.5171856
240.6*97.54757334
240.9*66.71559798
241.2*69.46929555
241.5*77.42916558
241.8*76.19309346
242.1*79.14300307
242.4*48.69656685
242.7*71.81899337
243*71.00691989
243.3*65.95670001
243.6*69.62461555
243.9*74.21729781
244.2*56.60792823
244.5*57.4147062
244.8*77.78670885
245.1*43.55421105
245.4*71.00216768
245.7*68.66398908
246*55.57029196
246.3*61.26805697
246.6*66.60418533
246.9*75.86037677
247.2*58.98042705
247.5*67.44448615
247.8*68.77200497
248.1*62.41624076
248.4*59.19396588
248.7*52.23350086
249*72.93649427
249.3*34.31314859
249.6*62.5230604
249.9*55.68845911
250.2*66.77985563
250.5*81.62926116
250.8*68.90573066
251.1*96.5198438
251.4*57.88854696
251.7*85.29648913
252*60.37599053
252.3*80.73560016
252.6*87.52283797
252.9*69.46896379
253.2*77.83267192
253.5*76.43263108
253.8*64.36219028
254.1*84.43700709
254.4*59.02426713
254.7*87.76411897
255*70.02280967
255.3*81.65648609
255.6*70.07463943
255.9*73.87114805
256.2*73.55903059
256.5*63.11038018
256.8*73.510756
257.1*76.60261923
257.4*65.37165127
257.7*52.06813452
258*92.98690691
258.3*65.71659166
258.6*87.29701347
258.9*78.18319545
259.2*86.64364649
259.5*57.40226761
259.8*51.17047533
260.1*57.63667652
260.4*51.74960214
260.7*69.89601184
261*68.78201368
261.3*79.41055792
261.6*92.67858792
261.9*79.59550032
262.2*83.43172952
262.5*79.79022765
262.8*57.11853834
263.1*64.95003959
263.4*59.90033004
263.7*53.93840374
264*76.04131597
264.3*60.74935087
264.6*72.16004024
264.9*79.60767579
265.2*75.66370909
265.5*92.79569324
265.8*87.60602727
266.1*57.90338432
266.4*92.18986159
266.7*60.73883305
267*80.30361022
267.3*74.46266053
267.6*59.5429886
267.9*78.39482535
268.2*76.69122047
268.5*63.48010559
268.8*74.87383156
269.1*77.48716676
269.4*64.25513187
269.7*78.14865176
270*96.70874289
270.3*70.805855
270.6*70.09414713
270.9*64.65592543
271.2*40.80114879
271.5*39.14290232
271.8*74.4339835
272.1*96.92335345
272.4*72.77398026
272.7*93.64652634
273*84.87341765
273.3*65.93943777
273.6*75.90246723
273.9*67.29084051
274.2*70.71766488
274.5*75.67371663
274.8*60.77669354
275.1*91.71917568
275.4*76.31055526
275.7*75.29897655
276*73.01071147
276.3*83.72091863
276.6*79.46578559
276.9*65.34630053
277.2*81.44698895
277.5*71.84079626
277.8*96.78795558
278.1*76.18584975
278.4*93.24614179
278.7*86.52590101
279*70.43906958
279.3*72.52656415
279.6*73.37619861
279.9*65.49994924
280.2*87.72054351
280.5*96.0457582
280.8*86.07339874
281.1*88.79549653
281.4*80.98022457
281.7*79.71455806
282*67.94728368
282.3*83.67850316
282.6*78.13198232
282.9*90.81162775
283.2*69.68907892
283.5*96.81032238
283.8*63.34542195
284.1*79.86129375
284.4*70.88499049
284.7*53.8531334
285*80.88076021
285.3*80.33760442
285.6*76.50905666
285.9*84.1911172
286.2*93.05087606
286.5*102.514077
286.8*88.03618125
287.1*80.24170154
287.4*70.75956876
287.7*73.78929741
288*86.764013
288.3*80.47532686
288.6*59.43542747
288.9*84.34410701
289.2*85.93837845
289.5*78.81485767
289.8*93.415555
290.1*74.31661967
290.4*78.41934151
290.7*84.65321573
291*99.21481119
291.3*60.34369007
291.6*76.20913415
291.9*77.42469225
292.2*71.67248273
292.5*74.09169052
292.8*95.70355096
293.1*91.07495603
293.4*96.51855695
293.7*77.77356875
294*106.1170384
294.3*51.97178307
294.6*82.13114891
294.9*79.45165593
295.2*90.40422443
295.5*75.51941666
295.8*93.4529978
296.1*41.36503246
296.4*61.70545469
296.7*73.75936081
297*68.95540863
297.3*73.58158512
297.6*87.28218275
297.9*107.9349423
298.2*67.81441806
298.5*82.43218538
298.8*94.04097893
299.1*75.02216959
299.4*85.80354651
299.7*76.19433649
300*102.3527488
300.3*87.15446185
300.6*103.5948474
300.9*79.05487812
301.2*84.00068656
301.5*84.85810019
301.8*85.70284231
302.1*95.62020488
302.4*75.36408414
302.7*94.53056617
303*77.39256348
303.3*77.34127793
303.6*74.42638993
303.9*67.99838049
304.2*90.9352189
304.5*79.01747195
304.8*73.66283259
305.1*92.38125031
305.4*89.50484909
305.7*78.39710823
306*73.93249205
306.3*90.49053148
306.6*79.2488802
306.9*85.72957952
307.2*82.24617215
307.5*81.56622818
307.8*80.46912037
308.1*84.7386581
308.4*76.83879749
308.7*60.71110272
309*84.84852995
309.3*72.96692275
309.6*92.48843786
309.9*100.0648071
310.2*81.72581083
310.5*86.34357243
310.8*83.11363536
311.1*80.87286649
311.4*82.63799137
311.7*93.3432792
312*86.45670771
312.3*94.77360535
312.6*85.45577887
312.9*97.68825651
313.2*82.38716206
313.5*101.1125754
313.8*92.82853095
314.1*82.08622545
314.4*88.1442355
314.7*74.05440396
315*78.47412007
315.3*84.8421099
315.6*82.76376379
315.9*103.2265003
316.2*92.12443391
316.5*71.47725604
316.8*87.81417788
317.1*76.99637736
317.4*84.03208702
317.7*99.83819618
318*99.18724579
318.3*86.30423439
318.6*105.3828488
318.9*83.78345377
319.2*95.81647316
319.5*99.88505723
319.8*79.70697004
320.1*80.86457347
320.4*80.4368144
320.7*91.04844925
321*85.46103375
321.3*81.04482389
321.6*109.9013649
321.9*82.62827687
322.2*83.46363241
322.5*73.11634288
322.8*79.91945593
323.1*75.97453149
323.4*93.58998142
323.7*108.9576614
324*99.43003201
324.3*98.30927987
324.6*110.1371083
324.9*89.34646394
325.2*69.24827965
325.5*92.89789845
325.8*86.53045379
326.1*94.72242633
326.4*81.88943596
326.7*81.27689904
327*75.1875364
327.3*79.70305992
327.6*98.87482372
327.9*90.79840604
328.2*87.54069023
328.5*59.88396906
328.8*100.044679
329.1*57.80470845
329.4*69.33267384
329.7*80.31553775
330*79.55292359
330.3*66.18037724
330.6*98.53141402
330.9*81.17608199
331.2*85.14138091
331.5*82.94781198
331.8*79.93456384
332.1*87.9723034
332.4*68.27419473
332.7*98.50299952
333*72.2636459
333.3*84.96662841
333.6*69.69169639
333.9*84.87252639
334.2*77.17717852
334.5*50.73027904
334.8*108.0287769
335.1*88.50190102
335.4*102.9893923
335.7*97.32580374
336*63.01121517
336.3*87.3305734
336.6*84.17355196
336.9*80.7226275
337.2*121.5806179
337.5*99.23259623
337.8*75.20780433
338.1*97.70938714
338.4*97.2085352
338.7*94.78508138
339*98.61143708
339.3*113.4687081
339.6*85.14983021
339.9*84.69292404
340.2*71.20480996
340.5*96.36172688
340.8*82.90615392
341.1*92.75682282
341.4*81.98450463
341.7*99.40554755
342*82.64557262
342.3*102.7819698
342.6*86.24844102
342.9*80.13730345
343.2*92.59437959
343.5*102.3498338
343.8*86.73559076
344.1*97.96170434
344.4*82.40925433
344.7*89.23057616
345*89.00926564
345.3*82.32971561
345.6*95.46745506
345.9*83.87415951
346.2*117.3199041
346.5*65.15328857
346.8*94.73642011
347.1*89.56211023
347.4*88.3228303
347.7*93.30762364
348*72.04716198
348.3*94.16817055
348.6*98.49029922
348.9*114.185631
349.2*78.49002108
349.5*89.3364476
349.8*84.56174588
350.1*107.0564169
350.4*102.5580913
350.7*98.51132619
351*87.59602324
351.3*72.35083804
351.6*86.52076904
351.9*83.26959163
352.2*92.77661888
352.5*68.80287315
352.8*103.7363263
353.1*82.68561571
353.4*102.0293789
353.7*98.53707588
354*85.96885972
354.3*104.6578082
354.6*88.19361969
354.9*93.16240596
355.2*106.1057933
355.5*94.67485404
355.8*99.06789999
356.1*95.12649837
356.4*91.55591518
356.7*94.34350682
357*95.78797853
357.3*80.27198227
357.6*93.20390801
357.9*93.68963579
358.2*100.3787824
358.5*95.26931985
358.8*92.19591158
359.1*77.45206179
359.4*102.4999252
359.7*88.36871647